Workbook

Sheet Change_Log
A1: Step | B1: Dataset Affected | C1: Action | D1: Details / Rationale | E1: Formula(s) Used
A2: 1 | B2: Raw_TRM_Cop_Usd | C2: Included TRM data | D2: Added TRM values to enable cacao price conversion to USD. | E2: —
C3: Created month_ref column | D3: Generated monthly reference for aggregation and joining. | E3: DATE(YEAR(A2), MONTH(A2), 1)
A4: 1.1 | B4: Cleaned_TRM_Cop_Usd | C4: Created month_ref column (B:B) | D4: Used as reference to match with Monthly_Colombian_Cacao for calculations. | E4: DATE(YEAR(A3), MONTH(A3), 1)
C5: Created cacao–USD conversion table | D5: Stored in Monthly_TRM_Cop_Usd. | E5: —
A6: 1.2 | B6: Monthly_TRM_Cop_Usd | C6: Created table for monthly TRM | D6: Calculated average TRM for each month (column trm_average_month). | E6: AVERAGEIF(Cleaned_TRM_Cop_Usd!B:B, A2, Cleaned_TRM_Cop_Usd!C:C)
A7: 2 | B7: Raw_Pipeline_Colombian_Cacao | C7: Created cleaning pipeline | D7: Initial pipeline to clean and standardize Colombian cacao price data. | E7: —
C8: Replaced commas (D:D) | D8: Replaced commas with dots to standardize decimal format. | E8: SUBSTITUTE(C2, ",", ".")
C9: Fixed malformed decimals (E:E) | D9: Removed the first of two dots in cases where two decimal points were present. | E9: IF(LEN(D2)-LEN(SUBSTITUTE(D2,".",""))>=2, SUBSTITUTE(D2,".","",1), D2)
C10: Trimmed whitespace & removed non-printable characters (F:F) | D10: Removed leading/trailing spaces and ASCII noise (CHAR(160), UNICHAR(8203), CHAR(10/13)). | E10: TRIM(CLEAN(SUBSTITUTE(SUBSTITUTE(G2,CHAR(160),""),UNICHAR(8203),"")))
C11: Converted to numeric (G:G) | D11: Ensured values were recognized as numeric. | E11: VALUE(F2)
C12: Validated integrity (H:H) | D12: Verified length and numeric format of cleaned values. | E12: LEN(G2), ISNUMBER(G2)
A13: 2.1 | B13: Raw2_Pipeline_Colombian_Cacao | C13: Added missing price data | D13: Included additional dataset covering 22 July 2024 – 3 August 2025. | E13: —
C14: Created second cleaning pipeline | D14: Applied the same structure used for the first raw dataset. | E14: —
C15: Cleaned Week column (B:B) | D15: Standardized “30 al 05” into “30 - 5”. | E15: LEFT(B2, FIND("al", B2)-2) / RIGHT(B2, FIND("al", B2)-2) / =E2 & " - " & F2
C16: Extracted year (D:D) | D16: Isolated 4-digit year from text. | E16: IFERROR(MID(A2, FIND("202", A2), 4), "")
C17: Standardized month numbers (E:E) | D17: Converted Spanish month names to their numeric equivalent (1–12). | E17: CHOOSE(MATCH(TRUE, ISNUMBER(SEARCH({"enero",...,"diciembre"}, LOWER(A2))), 0), 1, …, 12)
C18: Standardized date format (F:F) | D18: Concatenated Year and Month into uniform date structure. | E18: CONCAT(E2,"/1/",D2)
C19: Applied cleaning pipeline | D19: Used same G–K column structure as the first pipeline. | E19: —
A20: 2.2 | B20: Cleaned_Colombian_Cacao | C20: Merged cleaned datasets (B:B) | D20: Consolidated both pipelines and manually added missing date/price entries. | E20: —
C21: Filled missing date ranges | D21: Included 22–28 July 2024 and 28 July–3 August 2025. | E21: —
C22: Recalculated monthly averages | D22: Final averages stored in Monthly_Colombian_Cacao. | E22: —
C23: Standarized Week format to export (C:C) | D23: Changed "-" to "–" to prevent formatting issues. | E23: SUBSTITUTE(B2,"-","–")
A24: 2.3 | B24: Monthly_Colombian_Cacao | C24: month_sum (B:B) | D24: Total price per month. | E24: SUMIF(Cleaned_Colombian_Cacao!$A:$A, A2, Cleaned_Colombian_Cacao!$C:$C)
C25: number_weeks (C:C) | D25: Number of price observations per month. | E25: COUNTIF(Cleaned_Colombian_Cacao!$A:$A, A2)
C26: avg_month (D:D) | D26: Average price per month. | E26: month_sum / number_weeks
C27: trm_usd (E:E) | D27: Monthly TRM lookup. | E27: XLOOKUP(A2, Monthly_TRM_Cop_Usd!A:A, Monthly_TRM_Cop_Usd!B:B, "Not found")
C28: price_usd_metric_kilogram (F:F) | D28: Cacao price in USD per kg. | E28: avg_month / trm_usd
C29: price_usd_metric_ton (G:G) | D29: Cacao price in USD per metric ton. | E29: F2 * 1000
A30: 3 | B30: Cleaned_Global_Cacao | C30: Renamed columns | D30: Standardized column names to match overall schema. | E30: —
A31: 4 | B31: Raw_Trade_WITS | C31: Merged data (2013–2024) | D31: Combined annual export data into a single worksheet. | E31: —
C32: Filtered by HS codes | D32: Retained only HS codes 180631 and 180632 (chocolate bars). | E32: —
A33: 5 | B33: Raw_Chocolate_Producer_Price | C33: No changes | D33: Dataset used as provided. | E33: —
A34: 5.1 | B34: Cleaned_Chocolate_Producer_Pric | C34: Renamed columns | D34: Changed the column name PCU3113513113514 with producer_price_index | E34: —
A35: 6 | B35: Cleaned_Trade_WITS | C35: Fixed ISO3 formatting | D35: Removed trailing spaces in ReporterISO3 (e.g., 531 — Curaçao). | E35: —
A36: 7 | B36: All Clean Datasets | C36: Renamed columns | D36: Converted headers to snake_case for SQL compatibility. | E36: —

Sheet Pivot_Global_Cacao
A1: Row Labels | B1: Average of price_cocoa_usd_metric_ton
A2: 2013 | B2: 2439.0935 | K2: Outliers
A3: 2014 | B3: 3062.7681 | K3: Max | L3: =MAX(B2:B13) -> 7390.5643 | M3: =_xlfn.XLOOKUP(L3,$B$2:$B$37,$A$2:$A$37) -> 2024
A4: 2015 | B4: 3135.1663 | K4: Min | L4: =MIN(B2:B13) -> 2029.3379 | M4: =_xlfn.XLOOKUP(L4,$B$2:$B$37,$A$2:$A$37) -> 2017
A5: 2016 | B5: 2891.2566
A6: 2017 | B6: 2029.3379
A7: 2018 | B7: 2293.7391
A8: 2019 | B8: 2340.8215
A9: 2020 | B9: 2369.9582
A10: 2021 | B10: 2425.5182
A11: 2022 | B11: 2369.4029
A12: 2023 | B12: 3258.0444
A13: 2024 | B13: 7390.5643
A14: 2025 | B14: 9143.1143
A15: Grand Total | B15: 3206.6015

Sheet Pivot_Colombian_Cacao
A1: Row Labels | B1: Average of price_usd_metric_ton
A2: 2013 | B2: 2302.5961
A3: 2014 | B3: 2680.4493
A4: 2015 | B4: 2562.1075
A5: 2016 | B5: 2571.9266
A6: 2017 | B6: 1775.6757
A7: 2018 | B7: 1984.2303
A8: 2019 | B8: 2045.3231
A9: 2020 | B9: 2192.7355
A10: 2021 | B10: 2085.2984
A11: 2022 | B11: 2075.8383
A12: 2023 | B12: 2841.5998
A13: 2024 | B13: 6817.412
... A15: Grand Total | B15: 2873.9495

Sheet Pivot_Global_Chocolate_Price
A1: Row Labels | B1: Average of TradeValue_in_1000_USD
A2: 2013 | B2: 49863.692
A3: 2014 | B3: 50805.28
A4: 2015 | B4: 40407.231
A5: 2016 | B5: 41277.383
A6: 2017 | B6: 43861.574
A7: 2018 | B7: 46180.87
A8: 2019 | B8: 48757.197
A9: 2020 | B9: 51450.346
A10: 2021 | B10: 55668.495
A11: 2022 | B11: 59525.415
A12: 2023 | B12: 71552.28
A13: 2024 | B13: 112082.46
A14: Grand Total | B14: 54378.081

Sheet Pivot_Chocolate_Producer_Price
A1: Row Labels | B1: Average of PCU3113513113514
A2: 2011 | B2: 100
A3: 2012 | B3: 100
A4: 2013 | B4: 100
A5: 2014 | B5: 102.75833
A6: 2015 | B6: 107.525
A7: 2016 | B7: 105.9
A8: 2017 | B8: 103.325
A9: 2018 | B9: 103.73333
A10: 2019 | B10: 105.59167
A11: 2020 | B11: 107.39167
A12: 2021 | B12: 117.96317
A13: 2022 | B13: 123.13967
... A17: Grand Total | B17: 112.92883

Sheet Pivot_ComTrade
A1: cmdCode | B1: 180632
A3: Row Labels | B3: Sum of primaryValue | C3: Sum of netWgt
A4: 2016 | B4: 5056584.4 | C4: 635873.94
A5: 1 | B5: 369324.1 | C5: 35819.48
A6: 2 | B6: 309226.41 | C6: 32432.19
A7: 3 | B7: 491508.12 | C7: 55623.96
A8: 4 | B8: 338455.55 | C8: 45396.27
A9: 5 | B9: 510499.9 | C9: 54651.22
A10: 6 | B10: 519692.59 | C10: 52378.52
A11: 7 | B11: 278978.4 | C11: 36384.12
A12: 8 | B12: 360747.73 | C12: 62059.56
A13: 9 | B13: 326355.06 | C13: 42964.09
A14: 10 | B14: 635123.37 | C14: 87331.55
A15: 11 | B15: 580691.73 | C15: 66369.36
... A107: 12 | B107: 323255.5 | C107: 42847.1
A108: Grand Total | B108: 35318997 | C108: 4682041.8

Sheet Pivot_Chocolate_Exports
A1: ReporterISO3 | B1: (All)
A3: Row Labels | B3: Sum of TradeValue_in_1000_USD
A4: 180631 | B4: 70699565
A5: 2013 | B5: 5106212.8
A6: 2014 | B6: 5420678.1
A7: 2015 | B7: 4780569.8
A8: 2016 | B8: 4861932.8
A9: 2017 | B9: 5167420.7
A10: 2018 | B10: 5446620.8
A11: 2019 | B11: 5259863.1
A12: 2020 | B12: 5286025.2
A13: 2021 | B13: 6189241.2
A14: 2022 | B14: 6694108.2
A15: 2023 | B15: 7990179.1
... A29: 2024 | B29: 8988150.9
A30: Grand Total | B30: 1.4437381e+08

Sheet Raw_TRM_Cop_Usd
A1: Periodo(MMM DD, AAAA) | B1: Tasa Representativa del Mercado (TRM)
A2: 33569 | B2: 693.32
A3: 33570 | B3: 693.99
A4: 33571 | B4: 694.7
A5: 33572 | B5: 694.7
A6: 33573 | B6: 643.42
A7: 33574 | B7: 643.42
A8: 33575 | B8: 639.22
A9: 33576 | B9: 635.7
A10: 33577 | B10: 631.51
A11: 33578 | B11: 627.16
A12: 33579 | B12: 638.06
A13: 33580 | B13: 638.06
... A12286: 45853 | B12286: 4011.79

Sheet Cleaned_TRM_Cop_Usd
A1: date | B1: month_ref | C1: trm
A2: 33569 | B2: =DATE(YEAR(A2), MONTH(A2), 1) -> 33543 | C2: 693.32
A3: 33570 | B3: =DATE(YEAR(A3), MONTH(A3), 1) -> 33543 | C3: 693.99
A4: 33571 | B4: =DATE(YEAR(A4), MONTH(A4), 1) -> 33543 | C4: 694.7
A5: 33572 | B5: =DATE(YEAR(A5), MONTH(A5), 1) -> 33543 | C5: 694.7
A6: 33573 | B6: =DATE(YEAR(A6), MONTH(A6), 1) -> 33573 | C6: 643.42
A7: 33574 | B7: =DATE(YEAR(A7), MONTH(A7), 1) -> 33573 | C7: 643.42
A8: 33575 | B8: =DATE(YEAR(A8), MONTH(A8), 1) -> 33573 | C8: 639.22
A9: 33576 | B9: =DATE(YEAR(A9), MONTH(A9), 1) -> 33573 | C9: 635.7
A10: 33577 | B10: =DATE(YEAR(A10), MONTH(A10), 1) -> 33573 | C10: 631.51
A11: 33578 | B11: =DATE(YEAR(A11), MONTH(A11), 1) -> 33573 | C11: 627.16
A12: 33579 | B12: =DATE(YEAR(A12), MONTH(A12), 1) -> 33573 | C12: 638.06
A13: 33580 | B13: =DATE(YEAR(A13), MONTH(A13), 1) -> 33573 | C13: 638.06
... A12286: 45853 | B12286: =DATE(YEAR(A12286), MONTH(A12286), 1) -> 45839 | C12286: 4011.79

Sheet Monthly_TRM_Cop_Usd
A1: date | B1: trm_average_month
A2: 33543 | B2: =AVERAGEIF(Cleaned_TRM_Cop_Usd!B:B,A2,Cleaned_TRM_Cop_Usd!C:C) -> 694.1775
A3: 33573 | B3: =AVERAGEIF(Cleaned_TRM_Cop_Usd!B:B,A3,Cleaned_TRM_Cop_Usd!C:C) -> 630.41258
A4: 33604 | B4: =AVERAGEIF(Cleaned_TRM_Cop_Usd!B:B,A4,Cleaned_TRM_Cop_Usd!C:C) -> 644.05806
A5: 33635 | B5: =AVERAGEIF(Cleaned_TRM_Cop_Usd!B:B,A5,Cleaned_TRM_Cop_Usd!C:C) -> 635.67172
A6: 33664 | B6: =AVERAGEIF(Cleaned_TRM_Cop_Usd!B:B,A6,Cleaned_TRM_Cop_Usd!C:C) -> 640.50194
A7: 33695 | B7: =AVERAGEIF(Cleaned_TRM_Cop_Usd!B:B,A7,Cleaned_TRM_Cop_Usd!C:C) -> 649.955
A8: 33725 | B8: =AVERAGEIF(Cleaned_TRM_Cop_Usd!B:B,A8,Cleaned_TRM_Cop_Usd!C:C) -> 659.77129
A9: 33756 | B9: =AVERAGEIF(Cleaned_TRM_Cop_Usd!B:B,A9,Cleaned_TRM_Cop_Usd!C:C) -> 677.16533
A10: 33786 | B10: =AVERAGEIF(Cleaned_TRM_Cop_Usd!B:B,A10,Cleaned_TRM_Cop_Usd!C:C) -> 704.77226
A11: 33817 | B11: =AVERAGEIF(Cleaned_TRM_Cop_Usd!B:B,A11,Cleaned_TRM_Cop_Usd!C:C) -> 694.17452
A12: 33848 | B12: =AVERAGEIF(Cleaned_TRM_Cop_Usd!B:B,A12,Cleaned_TRM_Cop_Usd!C:C) -> 697.50333
A13: 33878 | B13: =AVERAGEIF(Cleaned_TRM_Cop_Usd!B:B,A13,Cleaned_TRM_Cop_Usd!C:C) -> 707.80484
... A406: 45839 | B406: =AVERAGEIF(Cleaned_TRM_Cop_Usd!B:B,A406,Cleaned_TRM_Cop_Usd!C:C) -> 4010.7213

Sheet Raw_Colombian_Cacao
B5: Precio Compra Cacao Nacional ($/Kg)
B6: 41456 | C6: 1 al 7 | D6: 3762.5
C7: 8 al 14 | D7: 3797.5
C8: 15 al 21 | D8: 3737.5
C9: 22 al 28 | D9: 3797.5
B10: 41487 | C10: 29 al 4 | D10: 3937.5
C11: 5 al 11 | D11: 3897.5
C12: 12 al 18 | D12: 4012.5
C13: 19 al 25 | D13: 4137.5
C14: 26 al 1 | D14: 4217.5
B15: 41518 | C15: 2 al 8 | D15: 4287.5
C16: 9 al 15 | D16: 4287.5
C17: 16 al 22 | D17: 4462.5
C18: 23 al 29 | D18: 4477.5
B19: 41548 | C19: 30 al 6 | D19: 4437.5
C20: 7 al 13 | D20: 4487.5
C21: 14 al 20 | D21: 4637.5
C22: 21 al 27 | D22: 4687.5
C23: 28 al 3 | D23: 4687.5
B24: 41579 | C24: 4 al 10 | D24: 4675
C25: 11 al 17 | D25: 4712.5
C26: 18 al 24 | D26: 4712.5
C27: 25 al 30 | D27: 4837.5
B28: 41609 | C28: 2 al 8 | D28: 4887.5
C29: 9 al 15 | D29: 4887.5
C30: 16 al 22 | D30: 4887.5
C31: 23 al 29 | D31: 4887.5
B32: 41640 | C32: 30 al 5 | D32: 4887.5
C33: 6 al 12 | D33: 4887.5
C34: 13 al 19 | D34: 4687.5
C35: 20 al 26 | D35: 4737.5
B36: 41671 | C36: 27 al 2 | D36: 4737.5
C37: 3 al 9 | D37: 4937.5
C38: 10 al 16 | D38: 5087.5
C39: 17 al22 | D39: 5087.5
C40: 23 al 28 | D40: 5300
B41: 41699 | C41: 3 al 9 | D41: 5325
C42: 10 al 16 | D42: 5375
C43: 17 al 23 | D43: 5375
C44: 24 al 30 | D44: 5475
...

Sheet Raw_Pipeline_Colombian_Cacao
A1: date | B1: week | C1: price_cop_per_kg | D1: Change "," | E1: Remove first . | F1: Clean | G1: price_cop_per_kg | H1: isnumber | I1: len
A2: 41456 | B2: 1 al 7 | C2: 3762.5 | D2: =SUBSTITUTE(C2, ",", ".") -> 3762.5 | E2: =IF(LEN(D2)-LEN(SUBSTITUTE(D2,".",""))>=2, SUBSTITUTE(D2,".","",1), D2) -> 3762.5 | F2: =TRIM(CLEAN( SUBSTITUTE( SUBSTITUTE( SUBSTITUTE( SUBSTITUTE(E2, CHAR(160), ""), _xlfn.UNICHAR(8203), "" ), "/kg", "" ), "$", "" ) )) -> 3762.5 | G2: =VALUE(F2) -> 3762.5 | H2: =ISNUMBER(G2) -> TRUE | I2: =LEN(G2) -> 6
A3: 41456 | B3: 8 al 14 | C3: 3797.5 | D3: =SUBSTITUTE(C3, ",", ".") -> 3797.5 | E3: =IF(LEN(D3)-LEN(SUBSTITUTE(D3,".",""))>=2, SUBSTITUTE(D3,".","",1), D3) -> 3797.5 | F3: =TRIM(CLEAN( SUBSTITUTE( SUBSTITUTE( SUBSTITUTE( SUBSTITUTE(E3, CHAR(160), ""), _xlfn.UNICHAR(8203), "" ), "/kg", "" ), "$", "" ) )) -> 3797.5 | G3: =VALUE(F3) -> 3797.5 | H3: =ISNUMBER(G3) -> TRUE | I3: =LEN(G3) -> 6
A4: 41456 | B4: 15 al 21 | C4: 3737.5 | D4: =SUBSTITUTE(C4, ",", ".") -> 3737.5 | E4: =IF(LEN(D4)-LEN(SUBSTITUTE(D4,".",""))>=2, SUBSTITUTE(D4,".","",1), D4) -> 3737.5 | F4: =TRIM(CLEAN( SUBSTITUTE( SUBSTITUTE( SUBSTITUTE( SUBSTITUTE(E4, CHAR(160), ""), _xlfn.UNICHAR(8203), "" ), "/kg", "" ), "$", "" ) )) -> 3737.5 | G4: =VALUE(F4) -> 3737.5 | H4: =ISNUMBER(G4) -> TRUE | I4: =LEN(G4) -> 6
A5: 41456 | B5: 22 al 28 | C5: 3797.5 | D5: =SUBSTITUTE(C5, ",", ".") -> 3797.5 | E5: =IF(LEN(D5)-LEN(SUBSTITUTE(D5,".",""))>=2, SUBSTITUTE(D5,".","",1), D5) -> 3797.5 | F5: =TRIM(CLEAN( SUBSTITUTE( SUBSTITUTE( SUBSTITUTE( SUBSTITUTE(E5, CHAR(160), ""), _xlfn.UNICHAR(8203), "" ), "/kg", "" ), "$", "" ) )) -> 3797.5 | G5: =VALUE(F5) -> 3797.5 | H5: =ISNUMBER(G5) -> TRUE | I5: =LEN(G5) -> 6
A6: 41487 | B6: 29 al 4 | C6: 3937.5 | D6: =SUBSTITUTE(C6, ",", ".") -> 3937.5 | E6: =IF(LEN(D6)-LEN(SUBSTITUTE(D6,".",""))>=2, SUBSTITUTE(D6,".","",1), D6) -> 3937.5 | F6: =TRIM(CLEAN( SUBSTITUTE( SUBSTITUTE( SUBSTITUTE( SUBSTITUTE(E6, CHAR(160), ""), _xlfn.UNICHAR(8203), "" ), "/kg", "" ), "$", "" ) )) -> 3937.5 | G6: =VALUE(F6) -> 3937.5 | H6: =ISNUMBER(G6) -> TRUE | I6: =LEN(G6) -> 6
A7: 41487 | B7: 5 al 11 | C7: 3897.5 | D7: =SUBSTITUTE(C7, ",", ".") -> 3897.5 | E7: =IF(LEN(D7)-LEN(SUBSTITUTE(D7,".",""))>=2, SUBSTITUTE(D7,".","",1), D7) -> 3897.5 | F7: =TRIM(CLEAN( SUBSTITUTE( SUBSTITUTE( SUBSTITUTE( SUBSTITUTE(E7, CHAR(160), ""), _xlfn.UNICHAR(8203), "" ), "/kg", "" ), "$", "" ) )) -> 3897.5 | G7: =VALUE(F7) -> 3897.5 | H7: =ISNUMBER(G7) -> TRUE | I7: =LEN(G7) -> 6
A8: 41487 | B8: 12 al 18 | C8: 4012.5 | D8: =SUBSTITUTE(C8, ",", ".") -> 4012.5 | E8: =IF(LEN(D8)-LEN(SUBSTITUTE(D8,".",""))>=2, SUBSTITUTE(D8,".","",1), D8) -> 4012.5 | F8: =TRIM(CLEAN( SUBSTITUTE( SUBSTITUTE( SUBSTITUTE( SUBSTITUTE(E8, CHAR(160), ""), _xlfn.UNICHAR(8203), "" ), "/kg", "" ), "$", "" ) )) -> 4012.5 | G8: =VALUE(F8) -> 4012.5 | H8: =ISNUMBER(G8) -> TRUE | I8: =LEN(G8) -> 6
A9: 41487 | B9: 19 al 25 | C9: 4137.5 | D9: =SUBSTITUTE(C9, ",", ".") -> 4137.5 | E9: =IF(LEN(D9)-LEN(SUBSTITUTE(D9,".",""))>=2, SUBSTITUTE(D9,".","",1), D9) -> 4137.5 | F9: =TRIM(CLEAN( SUBSTITUTE( SUBSTITUTE( SUBSTITUTE( SUBSTITUTE(E9, CHAR(160), ""), _xlfn.UNICHAR(8203), "" ), "/kg", "" ), "$", "" ) )) -> 4137.5 | G9: =VALUE(F9) -> 4137.5 | H9: =ISNUMBER(G9) -> TRUE | I9: =LEN(G9) -> 6
A10: 41487 | B10: 26 al 1 | C10: 4217.5 | D10: =SUBSTITUTE(C10, ",", ".") -> 4217.5 | E10: =IF(LEN(D10)-LEN(SUBSTITUTE(D10,".",""))>=2, SUBSTITUTE(D10,".","",1), D10) -> 4217.5 | F10: =TRIM(CLEAN( SUBSTITUTE( SUBSTITUTE( SUBSTITUTE( SUBSTITUTE(E10, CHAR(160), ""), _xlfn.UNICHAR(8203), "" ), "/kg", "" ), "$", "" ) )) -> 4217.5 | G10: =VALUE(F10) -> 4217.5 | H10: =ISNUMBER(G10) -> TRUE | I10: =LEN(G10) -> 6
A11: 41518 | B11: 2 al 8 | C11: 4287.5 | D11: =SUBSTITUTE(C11, ",", ".") -> 4287.5 | E11: =IF(LEN(D11)-LEN(SUBSTITUTE(D11,".",""))>=2, SUBSTITUTE(D11,".","",1), D11) -> 4287.5 | F11: =TRIM(CLEAN( SUBSTITUTE( SUBSTITUTE( SUBSTITUTE( SUBSTITUTE(E11, CHAR(160), ""), _xlfn.UNICHAR(8203), "" ), "/kg", "" ), "$", "" ) )) -> 4287.5 | G11: =VALUE(F11) -> 4287.5 | H11: =ISNUMBER(G11) -> TRUE | I11: =LEN(G11) -> 6
A12: 41518 | B12: 9 al 15 | C12: 4287.5 | D12: =SUBSTITUTE(C12, ",", ".") -> 4287.5 | E12: =IF(LEN(D12)-LEN(SUBSTITUTE(D12,".",""))>=2, SUBSTITUTE(D12,".","",1), D12) -> 4287.5 | F12: =TRIM(CLEAN( SUBSTITUTE( SUBSTITUTE( SUBSTITUTE( SUBSTITUTE(E12, CHAR(160), ""), _xlfn.UNICHAR(8203), "" ), "/kg", "" ), "$", "" ) )) -> 4287.5 | G12: =VALUE(F12) -> 4287.5 | H12: =ISNUMBER(G12) -> TRUE | I12: =LEN(G12) -> 6
A13: 41518 | B13: 16 al 22 | C13: 4462.5 | D13: =SUBSTITUTE(C13, ",", ".") -> 4462.5 | E13: =IF(LEN(D13)-LEN(SUBSTITUTE(D13,".",""))>=2, SUBSTITUTE(D13,".","",1), D13) -> 4462.5 | F13: =TRIM(CLEAN( SUBSTITUTE( SUBSTITUTE( SUBSTITUTE( SUBSTITUTE(E13, CHAR(160), ""), _xlfn.UNICHAR(8203), "" ), "/kg", "" ), "$", "" ) )) -> 4462.5 | G13: =VALUE(F13) -> 4462.5 | H13: =ISNUMBER(G13) -> TRUE | I13: =LEN(G13) -> 6
... A268: 43313 | B268: 13 al 19 | C268: 5350 | D268: =SUBSTITUTE(C268, ",", ".") -> 5350 | E268: =IF(LEN(D268)-LEN(SUBSTITUTE(D268,".",""))>=2, SUBSTITUTE(D268,".","",1), D268) -> 5350 | F268: =TRIM(CLEAN( SUBSTITUTE( SUBSTITUTE( SUBSTITUTE( SUBSTITUTE(E268, CHAR(160), ""), _xlfn.UNICHAR(8203), "" ), "/kg", "" ), "$", "" ) )) -> 5350 | G268: =VALUE(F268) -> 5350 | H268: =ISNUMBER(G268) -> TRUE | I268: =LEN(G268) -> 4
A269: 43313 | B269: 20 al 26 | C269: 5.506,70​​​ | D269: =SUBSTITUTE(C269, ",", ".") -> 5.506.70​​​ | E269: =IF(LEN(D269)-LEN(SUBSTITUTE(D269,".",""))>=2, SUBSTITUTE(D269,".","",1), D269) -> 5506.70​​​ | F269: =TRIM(CLEAN( SUBSTITUTE( SUBSTITUTE( SUBSTITUTE( SUBSTITUTE(E269, CHAR(160), ""), _xlfn.UNICHAR(8203), "" ), "/kg", "" ), "$", "" ) )) -> 5506.70 | G269: =VALUE(F269) -> 5506.7 | H269: =ISNUMBER(G269) -> TRUE | I269: =LEN(G269) -> 6
A270: 43313 | B270: 27 al 02 | C270: 5763.3 | D270: =SUBSTITUTE(C270, ",", ".") -> 5763.3 | E270: =IF(LEN(D270)-LEN(SUBSTITUTE(D270,".",""))>=2, SUBSTITUTE(D270,".","",1), D270) -> 5763.3 | F270: =TRIM(CLEAN( SUBSTITUTE( SUBSTITUTE( SUBSTITUTE( SUBSTITUTE(E270, CHAR(160), ""), _xlfn.UNICHAR(8203), "" ), "/kg", "" ), "$", "" ) )) -> 5763.3 | G270: =VALUE(F270) -> 5763.3 | H270: =ISNUMBER(G270) -> TRUE | I270: =LEN(G270) -> 6
A271: 43344 | B271: 03 al 09 | C271: 5948.3 | D271: =SUBSTITUTE(C271, ",", ".") -> 5948.3 | E271: =IF(LEN(D271)-LEN(SUBSTITUTE(D271,".",""))>=2, SUBSTITUTE(D271,".","",1), D271) -> 5948.3 | F271: =TRIM(CLEAN( SUBSTITUTE( SUBSTITUTE( SUBSTITUTE( SUBSTITUTE(E271, CHAR(160), ""), _xlfn.UNICHAR(8203), "" ), "/kg", "" ), "$", "" ) )) -> 5948.3 | G271: =VALUE(F271) -> 5948.3 | H271: =ISNUMBER(G271) -> TRUE | I271: =LEN(G271) -> 6
A272: 43344 | B272: 10 al 16 | C272: 6033.3 | D272: =SUBSTITUTE(C272, ",", ".") -> 6033.3 | E272: =IF(LEN(D272)-LEN(SUBSTITUTE(D272,".",""))>=2, SUBSTITUTE(D272,".","",1), D272) -> 6033.3 | F272: =TRIM(CLEAN( SUBSTITUTE( SUBSTITUTE( SUBSTITUTE( SUBSTITUTE(E272, CHAR(160), ""), _xlfn.UNICHAR(8203), "" ), "/kg", "" ), "$", "" ) )) -> 6033.3 | G272: =VALUE(F272) -> 6033.3 | H272: =ISNUMBER(G272) -> TRUE | I272: =LEN(G272) -> 6
A273: 43344 | B273: 17 al 23 | C273: 6033.3 | D273: =SUBSTITUTE(C273, ",", ".") -> 6033.3 | E273: =IF(LEN(D273)-LEN(SUBSTITUTE(D273,".",""))>=2, SUBSTITUTE(D273,".","",1), D273) -> 6033.3 | F273: =TRIM(CLEAN( SUBSTITUTE( SUBSTITUTE( SUBSTITUTE( SUBSTITUTE(E273, CHAR(160), ""), _xlfn.UNICHAR(8203), "" ), "/kg", "" ), "$", "" ) )) -> 6033.3 | G273: =VALUE(F273) -> 6033.3 | H273: =ISNUMBER(G273) -> TRUE | I273: =LEN(G273) -> 6
A274: 43344 | B274: 24 al 30 | C274: 5998.3 | D274: =SUBSTITUTE(C274, ",", ".") -> 5998.3 | E274: =IF(LEN(D274)-LEN(SUBSTITUTE(D274,".",""))>=2, SUBSTITUTE(D274,".","",1), D274) -> 5998.3 | F274: =TRIM(CLEAN( SUBSTITUTE( SUBSTITUTE( SUBSTITUTE( SUBSTITUTE(E274, CHAR(160), ""), _xlfn.UNICHAR(8203), "" ), "/kg", "" ), "$", "" ) )) -> 5998.3 | G274: =VALUE(F274) -> 5998.3 | H274: =ISNUMBER(G274) -> TRUE | I274: =LEN(G274) -> 6
A275: 43374 | B275: 1 al 7 | C275: 5730 | D275: =SUBSTITUTE(C275, ",", ".") -> 5730 | E275: =IF(LEN(D275)-LEN(SUBSTITUTE(D275,".",""))>=2, SUBSTITUTE(D275,".","",1), D275) -> 5730 | F275: =TRIM(CLEAN( SUBSTITUTE( SUBSTITUTE( SUBSTITUTE( SUBSTITUTE(E275, CHAR(160), ""), _xlfn.UNICHAR(8203), "" ), "/kg", "" ), "$", "" ) )) -> 5730 | G275: =VALUE(F275) -> 5730 | H275: =ISNUMBER(G275) -> TRUE | I275: =LEN(G275) -> 4
A276: 43374 | B276: 8 al 14 | C276: 5380 | D276: =SUBSTITUTE(C276, ",", ".") -> 5380 | E276: =IF(LEN(D276)-LEN(SUBSTITUTE(D276,".",""))>=2, SUBSTITUTE(D276,".","",1), D276) -> 5380 | F276: =TRIM(CLEAN( SUBSTITUTE( SUBSTITUTE( SUBSTITUTE( SUBSTITUTE(E276, CHAR(160), ""), _xlfn.UNICHAR(8203), "" ), "/kg", "" ), "$", "" ) )) -> 5380 | G276: =VALUE(F276) -> 5380 | H276: =ISNUMBER(G276) -> TRUE | I276: =LEN(G276) -> 4
A277: 43374 | B277: 15 al 21 | C277: 5505 | D277: =SUBSTITUTE(C277, ",", ".") -> 5505 | E277: =IF(LEN(D277)-LEN(SUBSTITUTE(D277,".",""))>=2, SUBSTITUTE(D277,".","",1), D277) -> 5505 | F277: =TRIM(CLEAN( SUBSTITUTE( SUBSTITUTE( SUBSTITUTE( SUBSTITUTE(E277, CHAR(160), ""), _xlfn.UNICHAR(8203), "" ), "/kg", "" ), "$", "" ) )) -> 5505 | G277: =VALUE(F277) -> 5505 | H277: =ISNUMBER(G277) -> TRUE | I277: =LEN(G277) -> 4
A278: 43374 | B278: 22 al 28 | C278: 5883.3 | D278: =SUBSTITUTE(C278, ",", ".") -> 5883.3 | E278: =IF(LEN(D278)-LEN(SUBSTITUTE(D278,".",""))>=2, SUBSTITUTE(D278,".","",1), D278) -> 5883.3 | F278: =TRIM(CLEAN( SUBSTITUTE( SUBSTITUTE( SUBSTITUTE( SUBSTITUTE(E278, CHAR(160), ""), _xlfn.UNICHAR(8203), "" ), "/kg", "" ), "$", "" ) )) -> 5883.3 | G278: =VALUE(F278) -> 5883.3 | H278: =ISNUMBER(G278) -> TRUE | I278: =LEN(G278) -> 6
A279: 43374 | B279: 29 al 04 | C279: 5921.7 | D279: =SUBSTITUTE(C279, ",", ".") -> 5921.7 | E279: =IF(LEN(D279)-LEN(SUBSTITUTE(D279,".",""))>=2, SUBSTITUTE(D279,".","",1), D279) -> 5921.7 | F279: =TRIM(CLEAN( SUBSTITUTE( SUBSTITUTE( SUBSTITUTE( SUBSTITUTE(E279, CHAR(160), ""), _xlfn.UNICHAR(8203), "" ), "/kg", "" ), "$", "" ) )) -> 5921.7 | G279: =VALUE(F279) -> 5921.7 | H279: =ISNUMBER(G279) -> TRUE | I279: =LEN(G279) -> 6
A280: 43405 | B280: 5 al 11 | C280: 6220 | D280: =SUBSTITUTE(C280, ",", ".") -> 6220 | E280: =IF(LEN(D280)-LEN(SUBSTITUTE(D280,".",""))>=2, SUBSTITUTE(D280,".","",1), D280) -> 6220 | F280: =TRIM(CLEAN( SUBSTITUTE( SUBSTITUTE( SUBSTITUTE( SUBSTITUTE(E280, CHAR(160), ""), _xlfn.UNICHAR(8203), "" ), "/kg", "" ), "$", "" ) )) -> 6220 | G280: =VALUE(F280) -> 6220 | H280: =ISNUMBER(G280) -> TRUE | I280: =LEN(G280) -> 4
A281: 43405 | B281: 12 al 18 | C281: 6333.3 | D281: =SUBSTITUTE(C281, ",", ".") -> 6333.3 | E281: =IF(LEN(D281)-LEN(SUBSTITUTE(D281,".",""))>=2, SUBSTITUTE(D281,".","",1), D281) -> 6333.3 | F281: =TRIM(CLEAN( SUBSTITUTE( SUBSTITUTE( SUBSTITUTE( SUBSTITUTE(E281, CHAR(160), ""), _xlfn.UNICHAR(8203), "" ), "/kg", "" ), "$", "" ) )) -> 6333.3 | G281: =VALUE(F281) -> 6333.3 | H281: =ISNUMBER(G281) -> TRUE | I281: =LEN(G281) -> 6
... A299: 43525 | B299: 18 al 24 | C299: 5976.2 | D299: =SUBSTITUTE(C299, ",", ".") -> 5976.2 | E299: =IF(LEN(D299)-LEN(SUBSTITUTE(D299,".",""))>=2, SUBSTITUTE(D299,".","",1), D299) -> 5976.2 | F299: =TRIM(CLEAN( SUBSTITUTE( SUBSTITUTE( SUBSTITUTE( SUBSTITUTE(E299, CHAR(160), ""), _xlfn.UNICHAR(8203), "" ), "/kg", "" ), "$", "" ) )) -> 5976.2 | G299: =VALUE(F299) -> 5976.2 | H299: =ISNUMBER(G299) -> TRUE | I299: =LEN(G299) -> 6
A300: 43525 | B300: 25 al 31 | C300: 5.778,7​​​​0​​​​ | D300: =SUBSTITUTE(C300, ",", ".") -> 5.778.7​​​​0​​​​ | E300: =IF(LEN(D300)-LEN(SUBSTITUTE(D300,".",""))>=2, SUBSTITUTE(D300,".","",1), D300) -> 5778.7​​​​0​​​​ | F300: =TRIM(CLEAN( SUBSTITUTE( SUBSTITUTE( SUBSTITUTE( SUBSTITUTE(E300, CHAR(160), ""), _xlfn.UNICHAR(8203), "" ), "/kg", "" ), "$", "" ) )) -> 5778.70 | G300: =VALUE(F300) -> 5778.7 | H300: =ISNUMBER(G300) -> TRUE | I300: =LEN(G300) -> 6
A301: 43556 | B301: 01 al 07 | C301: 5916 | D301: =SUBSTITUTE(C301, ",", ".") -> 5916 | E301: =IF(LEN(D301)-LEN(SUBSTITUTE(D301,".",""))>=2, SUBSTITUTE(D301,".","",1), D301) -> 5916 | F301: =TRIM(CLEAN( SUBSTITUTE( SUBSTITUTE( SUBSTITUTE( SUBSTITUTE(E301, CHAR(160), ""), _xlfn.UNICHAR(8203), "" ), "/kg", "" ), "$", "" ) )) -> 5916 | G301: =VALUE(F301) -> 5916 | H301: =ISNUMBER(G301) -> TRUE | I301: =LEN(G301) -> 4
A302: 43556 | B302: 08 al 14 | C302: 6205.7 | D302: =SUBSTITUTE(C302, ",", ".") -> 6205.7 | E302: =IF(LEN(D302)-LEN(SUBSTITUTE(D302,".",""))>=2, SUBSTITUTE(D302,".","",1), D302) -> 6205.7 | F302: =TRIM(CLEAN( SUBSTITUTE( SUBSTITUTE( SUBSTITUTE( SUBSTITUTE(E302, CHAR(160), ""), _xlfn.UNICHAR(8203), "" ), "/kg", "" ), "$", "" ) )) -> 6205.7 | G302: =VALUE(F302) -> 6205.7 | H302: =ISNUMBER(G302) -> TRUE | I302: =LEN(G302) -> 6
A303: 43556 | B303: 15 al 21 | C303: 6303.8 | D303: =SUBSTITUTE(C303, ",", ".") -> 6303.8 | E303: =IF(LEN(D303)-LEN(SUBSTITUTE(D303,".",""))>=2, SUBSTITUTE(D303,".","",1), D303) -> 6303.8 | F303: =TRIM(CLEAN( SUBSTITUTE( SUBSTITUTE( SUBSTITUTE( SUBSTITUTE(E303, CHAR(160), ""), _xlfn.UNICHAR(8203), "" ), "/kg", "" ), "$", "" ) )) -> 6303.8 | G303: =VALUE(F303) -> 6303.8 | H303: =ISNUMBER(G303) -> TRUE | I303: =LEN(G303) -> 6
A304: 43556 | B304: 22 al 28 | C304: 6361.8 | D304: =SUBSTITUTE(C304, ",", ".") -> 6361.8 | E304: =IF(LEN(D304)-LEN(SUBSTITUTE(D304,".",""))>=2, SUBSTITUTE(D304,".","",1), D304) -> 6361.8 | F304: =TRIM(CLEAN( SUBSTITUTE( SUBSTITUTE( SUBSTITUTE( SUBSTITUTE(E304, CHAR(160), ""), _xlfn.UNICHAR(8203), "" ), "/kg", "" ), "$", "" ) )) -> 6361.8 | G304: =VALUE(F304) -> 6361.8 | H304: =ISNUMBER(G304) -> TRUE | I304: =LEN(G304) -> 6
A305: 43586 | B305: 29 al 5 | C305: 6232 | D305: =SUBSTITUTE(C305, ",", ".") -> 6232 | E305: =IF(LEN(D305)-LEN(SUBSTITUTE(D305,".",""))>=2, SUBSTITUTE(D305,".","",1), D305) -> 6232 | F305: =TRIM(CLEAN( SUBSTITUTE( SUBSTITUTE( SUBSTITUTE( SUBSTITUTE(E305, CHAR(160), ""), _xlfn.UNICHAR(8203), "" ), "/kg", "" ), "$", "" ) )) -> 6232 | G305: =VALUE(F305) -> 6232 | H305: =ISNUMBER(G305) -> TRUE | I305: =LEN(G305) -> 4
A306: 43586 | B306: 6 al 12 | C306: 6453.5 | D306: =SUBSTITUTE(C306, ",", ".") -> 6453.5 | E306: =IF(LEN(D306)-LEN(SUBSTITUTE(D306,".",""))>=2, SUBSTITUTE(D306,".","",1), D306) -> 6453.5 | F306: =TRIM(CLEAN( SUBSTITUTE( SUBSTITUTE( SUBSTITUTE( SUBSTITUTE(E306, CHAR(160), ""), _xlfn.UNICHAR(8203), "" ), "/kg", "" ), "$", "" ) )) -> 6453.5 | G306: =VALUE(F306) -> 6453.5 | H306: =ISNUMBER(G306) -> TRUE | I306: =LEN(G306) -> 6
A307: 43586 | B307: 13 al 19 | C307: 6491.7 | D307: =SUBSTITUTE(C307, ",", ".") -> 6491.7 | E307: =IF(LEN(D307)-LEN(SUBSTITUTE(D307,".",""))>=2, SUBSTITUTE(D307,".","",1), D307) -> 6491.7 | F307: =TRIM(CLEAN( SUBSTITUTE( SUBSTITUTE( SUBSTITUTE( SUBSTITUTE(E307, CHAR(160), ""), _xlfn.UNICHAR(8203), "" ), "/kg", "" ), "$", "" ) )) -> 6491.7 | G307: =VALUE(F307) -> 6491.7 | H307: =ISNUMBER(G307) -> TRUE | I307: =LEN(G307) -> 6
A308: 43586 | B308: 20 al 26 | C308: 6.584,​​​​0​0​​​​ | D308: =SUBSTITUTE(C308, ",", ".") -> 6.584.​​​​0​0​​​​ | E308: =IF(LEN(D308)-LEN(SUBSTITUTE(D308,".",""))>=2, SUBSTITUTE(D308,".","",1), D308) -> 6584.​​​​0​0​​​​ | F308: =TRIM(CLEAN( SUBSTITUTE( SUBSTITUTE( SUBSTITUTE( SUBSTITUTE(E308, CHAR(160), ""), _xlfn.UNICHAR(8203), "" ), "/kg", "" ), "$", "" ) )) -> 6584.00 | G308: =VALUE(F308) -> 6584 | H308: =ISNUMBER(G308) -> TRUE | I308: =LEN(G308) -> 4
A309: 43617 | B309: 27 al 02 | C309: 6.918​,​​​​5​0 | D309: =SUBSTITUTE(C309, ",", ".") -> 6.918​.​​​​5​0 | E309: =IF(LEN(D309)-LEN(SUBSTITUTE(D309,".",""))>=2, SUBSTITUTE(D309,".","",1), D309) -> 6918​.​​​​5​0 | F309: =TRIM(CLEAN( SUBSTITUTE( SUBSTITUTE( SUBSTITUTE( SUBSTITUTE(E309, CHAR(160), ""), _xlfn.UNICHAR(8203), "" ), "/kg", "" ), "$", "" ) )) -> 6918.50 | G309: =VALUE(F309) -> 6918.5 | H309: =ISNUMBER(G309) -> TRUE | I309: =LEN(G309) -> 6
A310: 43617 | B310: 03 al 09 | C310: 6990 | D310: =SUBSTITUTE(C310, ",", ".") -> 6990 | E310: =IF(LEN(D310)-LEN(SUBSTITUTE(D310,".",""))>=2, SUBSTITUTE(D310,".","",1), D310) -> 6990 | F310: =TRIM(CLEAN( SUBSTITUTE( SUBSTITUTE( SUBSTITUTE( SUBSTITUTE(E310, CHAR(160), ""), _xlfn.UNICHAR(8203), "" ), "/kg", "" ), "$", "" ) )) -> 6990 | G310: =VALUE(F310) -> 6990 | H310: =ISNUMBER(G310) -> TRUE | I310: =LEN(G310) -> 4
A311: 43617 | B311: 10 al 16 | C311: 6880.5 | D311: =SUBSTITUTE(C311, ",", ".") -> 6880.5 | E311: =IF(LEN(D311)-LEN(SUBSTITUTE(D311,".",""))>=2, SUBSTITUTE(D311,".","",1), D311) -> 6880.5 | F311: =TRIM(CLEAN( SUBSTITUTE( SUBSTITUTE( SUBSTITUTE( SUBSTITUTE(E311, CHAR(160), ""), _xlfn.UNICHAR(8203), "" ), "/kg", "" ), "$", "" ) )) -> 6880.5 | G311: =VALUE(F311) -> 6880.5 | H311: =ISNUMBER(G311) -> TRUE | I311: =LEN(G311) -> 6
...

Sheet Raw2_Colombian_Cacao
A1: Fecha​​​​​​​​​​​​​​​ | B1: ​​Precio​​​​​
A2: 28 de julio al 3 de agosto de 2025​​​​​​ | B2: ​​$23.747,00​​/kg​
A3: 21 al 27 ​de julio de 2025​​​​​​ | B3: ​​$23.490,00​/kg​
A4: 14 al 20 ​de julio de 2025​​​​​​ | B4: ​​$25.323,00/kg​
A5: 7 al 13 de julio de 2025​​​​​​ | B5: ​​$25.977,50​​​/kg​
A6: 30 de junio al 6 d​e julio de 2025​​​​​​ | B6: ​​$27.960,70​​​/kg​
A7: 23 al 29 de junio de 2025​​​​​​ | B7: ​​$28.000,80​​/kg​
A8: 16 al 22 de junio de 2025​​​​​​ | B8: ​​$30.544,50​​/kg​
A9: 9 al 15 de junio de 2025​​​​ | B9: ​​$28.895,00​/kg​
A10: 2 al 8 de junio de 2025​​​​ | B10: ​​$27.863,50/kg​
A11: 26 de mayo al 1 de junio de 2025​​​​ | B11: ​​$31.486,50​​/kg​
A12: 19 al 25 de mayo de 2025​​​​ | B12: ​​$30.397,00​/kg​
... A206: 23 al 29 de agosto de 2021 ​​​​​ | B206: ​$8.208,50​​​​

Sheet Raw2_Pipeline_Colombian_Cacao
A1: Fecha​​​​​​​​​​​​​​​ | B1: date | C1: ​​Precio​​​​​ | D1: Year | E1: Month | F1: Date | G1: Clean | H1: Change "," | I1: Remove first dot | J1: price_cop_per_kg | K1: price_cop_per_kg
A2: 28 de julio al 3 de agosto de 2025​​​​​​ | B2: 28 al 3 | C2: ​​$23.747,00​​/kg​ | D2: =IFERROR(MID(A2,FIND("202",A2),4),"") -> 2025 | E2: {=CHOOSE(MATCH(TRUE,ISNUMBER(SEARCH({"enero","febrero","marzo","abril","mayo","junio","julio","agosto","septiembre","octubre","noviembre","diciembre"},LOWER(A2))),0), 1,2,3,4,5,6,7,8,9,10,11,12)} -> 7 | F2: =_xlfn.CONCAT(E2,"/1/",D2) -> 7/1/2025 | G2: =TRIM(CLEAN( SUBSTITUTE( SUBSTITUTE( SUBSTITUTE( SUBSTITUTE(C2, CHAR(160), ""), _xlfn.UNICHAR(8203), "" ), "/kg", "" ), "$", "" ) )) -> 23.747,00 | H2: =SUBSTITUTE(G2, ",", ".") -> 23.747.00 | I2: =SUBSTITUTE(H2, ".", "", 1) -> 23747.00 | J2: =VALUE(I2) -> 23747 | K2: =VALUE(J2) -> 23747
A3: 21 al 27 ​de julio de 2025​​​​​​ | B3: =LEFT(A3, FIND("de", A3)-2) -> 21 al 27 | C3: ​​$23.490,00​/kg​ | D3: =IFERROR(MID(A3,FIND("202",A3),4),"") -> 2025 | E3: {=CHOOSE(MATCH(TRUE,ISNUMBER(SEARCH({"enero","febrero","marzo","abril","mayo","junio","julio","agosto","septiembre","octubre","noviembre","diciembre"},LOWER(A3))),0), 1,2,3,4,5,6,7,8,9,10,11,12)} -> 7 | F3: =_xlfn.CONCAT(E3,"/1/",D3) -> 7/1/2025 | G3: =TRIM(CLEAN( SUBSTITUTE( SUBSTITUTE( SUBSTITUTE( SUBSTITUTE(C3, CHAR(160), ""), _xlfn.UNICHAR(8203), "" ), "/kg", "" ), "$", "" ) )) -> 23.490,00 | H3: =SUBSTITUTE(G3, ",", ".") -> 23.490.00 | I3: =SUBSTITUTE(H3, ".", "", 1) -> 23490.00 | J3: =VALUE(I3) -> 23490 | K3: =VALUE(J3) -> 23490
A4: 14 al 20 ​de julio de 2025​​​​​​ | B4: =LEFT(A4, FIND("de", A4)-2) -> 14 al 20 | C4: ​​$25.323,00/kg​ | D4: =IFERROR(MID(A4,FIND("202",A4),4),"") -> 2025 | E4: {=CHOOSE(MATCH(TRUE,ISNUMBER(SEARCH({"enero","febrero","marzo","abril","mayo","junio","julio","agosto","septiembre","octubre","noviembre","diciembre"},LOWER(A4))),0), 1,2,3,4,5,6,7,8,9,10,11,12)} -> 7 | F4: =_xlfn.CONCAT(E4,"/1/",D4) -> 7/1/2025 | G4: =TRIM(CLEAN( SUBSTITUTE( SUBSTITUTE( SUBSTITUTE( SUBSTITUTE(C4, CHAR(160), ""), _xlfn.UNICHAR(8203), "" ), "/kg", "" ), "$", "" ) )) -> 25.323,00 | H4: =SUBSTITUTE(G4, ",", ".") -> 25.323.00 | I4: =SUBSTITUTE(H4, ".", "", 1) -> 25323.00 | J4: =VALUE(I4) -> 25323 | K4: =VALUE(J4) -> 25323
A5: 7 al 13 de julio de 2025​​​​​​ | B5: =LEFT(A5, FIND("de", A5)-2) -> 7 al 13 | C5: ​​$25.977,50​​​/kg​ | D5: =IFERROR(MID(A5,FIND("202",A5),4),"") -> 2025 | E5: {=CHOOSE(MATCH(TRUE,ISNUMBER(SEARCH({"enero","febrero","marzo","abril","mayo","junio","julio","agosto","septiembre","octubre","noviembre","diciembre"},LOWER(A5))),0), 1,2,3,4,5,6,7,8,9,10,11,12)} -> 7 | F5: =_xlfn.CONCAT(E5,"/1/",D5) -> 7/1/2025 | G5: =TRIM(CLEAN( SUBSTITUTE( SUBSTITUTE( SUBSTITUTE( SUBSTITUTE(C5, CHAR(160), ""), _xlfn.UNICHAR(8203), "" ), "/kg", "" ), "$", "" ) )) -> 25.977,50 | H5: =SUBSTITUTE(G5, ",", ".") -> 25.977.50 | I5: =SUBSTITUTE(H5, ".", "", 1) -> 25977.50 | J5: =VALUE(I5) -> 25977.5 | K5: =VALUE(J5) -> 25977.5
A6: 30 de junio al 6 d​e julio de 2025​​​​​​ | B6: 30 al 6 | C6: ​​$27.960,70​​​/kg​ | D6: =IFERROR(MID(A6,FIND("202",A6),4),"") -> 2025 | E6: {=CHOOSE(MATCH(TRUE,ISNUMBER(SEARCH({"enero","febrero","marzo","abril","mayo","junio","julio","agosto","septiembre","octubre","noviembre","diciembre"},LOWER(A6))),0), 1,2,3,4,5,6,7,8,9,10,11,12)} -> 6 | F6: =_xlfn.CONCAT(E6,"/1/",D6) -> 6/1/2025 | G6: =TRIM(CLEAN( SUBSTITUTE( SUBSTITUTE( SUBSTITUTE( SUBSTITUTE(C6, CHAR(160), ""), _xlfn.UNICHAR(8203), "" ), "/kg", "" ), "$", "" ) )) -> 27.960,70 | H6: =SUBSTITUTE(G6, ",", ".") -> 27.960.70 | I6: =SUBSTITUTE(H6, ".", "", 1) -> 27960.70 | J6: =VALUE(I6) -> 27960.7 | K6: =VALUE(J6) -> 27960.7
A7: 23 al 29 de junio de 2025​​​​​​ | B7: =LEFT(A7, FIND("de", A7)-2) -> 23 al 29 | C7: ​​$28.000,80​​/kg​ | D7: =IFERROR(MID(A7,FIND("202",A7),4),"") -> 2025 | E7: {=CHOOSE(MATCH(TRUE,ISNUMBER(SEARCH({"enero","febrero","marzo","abril","mayo","junio","julio","agosto","septiembre","octubre","noviembre","diciembre"},LOWER(A7))),0), 1,2,3,4,5,6,7,8,9,10,11,12)} -> 6 | F7: =_xlfn.CONCAT(E7,"/1/",D7) -> 6/1/2025 | G7: =TRIM(CLEAN( SUBSTITUTE( SUBSTITUTE( SUBSTITUTE( SUBSTITUTE(C7, CHAR(160), ""), _xlfn.UNICHAR(8203), "" ), "/kg", "" ), "$", "" ) )) -> 28.000,80 | H7: =SUBSTITUTE(G7, ",", ".") -> 28.000.80 | I7: =SUBSTITUTE(H7, ".", "", 1) -> 28000.80 | J7: =VALUE(I7) -> 28000.8 | K7: =VALUE(J7) -> 28000.8
A8: 16 al 22 de junio de 2025​​​​​​ | B8: =LEFT(A8, FIND("de", A8)-2) -> 16 al 22 | C8: ​​$30.544,50​​/kg​ | D8: =IFERROR(MID(A8,FIND("202",A8),4),"") -> 2025 | E8: {=CHOOSE(MATCH(TRUE,ISNUMBER(SEARCH({"enero","febrero","marzo","abril","mayo","junio","julio","agosto","septiembre","octubre","noviembre","diciembre"},LOWER(A8))),0), 1,2,3,4,5,6,7,8,9,10,11,12)} -> 6 | F8: =_xlfn.CONCAT(E8,"/1/",D8) -> 6/1/2025 | G8: =TRIM(CLEAN( SUBSTITUTE( SUBSTITUTE( SUBSTITUTE( SUBSTITUTE(C8, CHAR(160), ""), _xlfn.UNICHAR(8203), "" ), "/kg", "" ), "$", "" ) )) -> 30.544,50 | H8: =SUBSTITUTE(G8, ",", ".") -> 30.544.50 | I8: =SUBSTITUTE(H8, ".", "", 1) -> 30544.50 | J8: =VALUE(I8) -> 30544.5 | K8: =VALUE(J8) -> 30544.5
A9: 9 al 15 de junio de 2025​​​​ | B9: =LEFT(A9, FIND("de", A9)-2) -> 9 al 15 | C9: ​​$28.895,00​/kg​ | D9: =IFERROR(MID(A9,FIND("202",A9),4),"") -> 2025 | E9: {=CHOOSE(MATCH(TRUE,ISNUMBER(SEARCH({"enero","febrero","marzo","abril","mayo","junio","julio","agosto","septiembre","octubre","noviembre","diciembre"},LOWER(A9))),0), 1,2,3,4,5,6,7,8,9,10,11,12)} -> 6 | F9: =_xlfn.CONCAT(E9,"/1/",D9) -> 6/1/2025 | G9: =TRIM(CLEAN( SUBSTITUTE( SUBSTITUTE( SUBSTITUTE( SUBSTITUTE(C9, CHAR(160), ""), _xlfn.UNICHAR(8203), "" ), "/kg", "" ), "$", "" ) )) -> 28.895,00 | H9: =SUBSTITUTE(G9, ",", ".") -> 28.895.00 | I9: =SUBSTITUTE(H9, ".", "", 1) -> 28895.00 | J9: =VALUE(I9) -> 28895 | K9: =VALUE(J9) -> 28895
A10: 2 al 8 de junio de 2025​​​​ | B10: =LEFT(A10, FIND("de", A10)-2) -> 2 al 8 | C10: ​​$27.863,50/kg​ | D10: =IFERROR(MID(A10,FIND("202",A10),4),"") -> 2025 | E10: {=CHOOSE(MATCH(TRUE,ISNUMBER(SEARCH({"enero","febrero","marzo","abril","mayo","junio","julio","agosto","septiembre","octubre","noviembre","diciembre"},LOWER(A10))),0), 1,2,3,4,5,6,7,8,9,10,11,12)} -> 6 | F10: =_xlfn.CONCAT(E10,"/1/",D10) -> 6/1/2025 | G10: =TRIM(CLEAN( SUBSTITUTE( SUBSTITUTE( SUBSTITUTE( SUBSTITUTE(C10, CHAR(160), ""), _xlfn.UNICHAR(8203), "" ), "/kg", "" ), "$", "" ) )) -> 27.863,50 | H10: =SUBSTITUTE(G10, ",", ".") -> 27.863.50 | I10: =SUBSTITUTE(H10, ".", "", 1) -> 27863.50 | J10: =VALUE(I10) -> 27863.5 | K10: =VALUE(J10) -> 27863.5
A11: 26 de mayo al 1 de junio de 2025​​​​ | B11: 26 al 1 | C11: ​​$31.486,50​​/kg​ | D11: =IFERROR(MID(A11,FIND("202",A11),4),"") -> 2025 | E11: {=CHOOSE(MATCH(TRUE,ISNUMBER(SEARCH({"enero","febrero","marzo","abril","mayo","junio","julio","agosto","septiembre","octubre","noviembre","diciembre"},LOWER(A11))),0), 1,2,3,4,5,6,7,8,9,10,11,12)} -> 5 | F11: =_xlfn.CONCAT(E11,"/1/",D11) -> 5/1/2025 | G11: =TRIM(CLEAN( SUBSTITUTE( SUBSTITUTE( SUBSTITUTE( SUBSTITUTE(C11, CHAR(160), ""), _xlfn.UNICHAR(8203), "" ), "/kg", "" ), "$", "" ) )) -> 31.486,50 | H11: =SUBSTITUTE(G11, ",", ".") -> 31.486.50 | I11: =SUBSTITUTE(H11, ".", "", 1) -> 31486.50 | J11: =VALUE(I11) -> 31486.5 | K11: =VALUE(J11) -> 31486.5
A12: 19 al 25 de mayo de 2025​​​​ | B12: =LEFT(A12, FIND("de", A12)-2) -> 19 al 25 | C12: ​​$30.397,00​/kg​ | D12: =IFERROR(MID(A12,FIND("202",A12),4),"") -> 2025 | E12: {=CHOOSE(MATCH(TRUE,ISNUMBER(SEARCH({"enero","febrero","marzo","abril","mayo","junio","julio","agosto","septiembre","octubre","noviembre","diciembre"},LOWER(A12))),0), 1,2,3,4,5,6,7,8,9,10,11,12)} -> 5 | F12: =_xlfn.CONCAT(E12,"/1/",D12) -> 5/1/2025 | G12: =TRIM(CLEAN( SUBSTITUTE( SUBSTITUTE( SUBSTITUTE( SUBSTITUTE(C12, CHAR(160), ""), _xlfn.UNICHAR(8203), "" ), "/kg", "" ), "$", "" ) )) -> 30.397,00 | H12: =SUBSTITUTE(G12, ",", ".") -> 30.397.00 | I12: =SUBSTITUTE(H12, ".", "", 1) -> 30397.00 | J12: =VALUE(I12) -> 30397 | K12: =VALUE(J12) -> 30397
A13: 12 al 18 de mayo de 2025​​​​ | B13: =LEFT(A13, FIND("de", A13)-2) -> 12 al 18 | C13: ​​$28.050,80​​/kg​ | D13: =IFERROR(MID(A13,FIND("202",A13),4),"") -> 2025 | E13: {=CHOOSE(MATCH(TRUE,ISNUMBER(SEARCH({"enero","febrero","marzo","abril","mayo","junio","julio","agosto","septiembre","octubre","noviembre","diciembre"},LOWER(A13))),0), 1,2,3,4,5,6,7,8,9,10,11,12)} -> 5 | F13: =_xlfn.CONCAT(E13,"/1/",D13) -> 5/1/2025 | G13: =TRIM(CLEAN( SUBSTITUTE( SUBSTITUTE( SUBSTITUTE( SUBSTITUTE(C13, CHAR(160), ""), _xlfn.UNICHAR(8203), "" ), "/kg", "" ), "$", "" ) )) -> 28.050,80 | H13: =SUBSTITUTE(G13, ",", ".") -> 28.050.80 | I13: =SUBSTITUTE(H13, ".", "", 1) -> 28050.80 | J13: =VALUE(I13) -> 28050.8 | K13: =VALUE(J13) -> 28050.8
A14: 5 al 11 de mayo de 2025​​​​ | B14: =LEFT(A14, FIND("de", A14)-2) -> 5 al 11 | C14: ​​$27.484,20​/kg​ | D14: =IFERROR(MID(A14,FIND("202",A14),4),"") -> 2025 | E14: {=CHOOSE(MATCH(TRUE,ISNUMBER(SEARCH({"enero","febrero","marzo","abril","mayo","junio","julio","agosto","septiembre","octubre","noviembre","diciembre"},LOWER(A14))),0), 1,2,3,4,5,6,7,8,9,10,11,12)} -> 5 | F14: =_xlfn.CONCAT(E14,"/1/",D14) -> 5/1/2025 | G14: =TRIM(CLEAN( SUBSTITUTE( SUBSTITUTE( SUBSTITUTE( SUBSTITUTE(C14, CHAR(160), ""), _xlfn.UNICHAR(8203), "" ), "/kg", "" ), "$", "" ) )) -> 27.484,20 | H14: =SUBSTITUTE(G14, ",", ".") -> 27.484.20 | I14: =SUBSTITUTE(H14, ".", "", 1) -> 27484.20 | J14: =VALUE(I14) -> 27484.2 | K14: =VALUE(J14) -> 27484.2
A15: 28 de abril al 4 de mayo de 2025​​​​ | B15: 28 al 4 | C15: ​​$27.686,70​​​/kg​ | D15: =IFERROR(MID(A15,FIND("202",A15),4),"") -> 2025 | E15: {=CHOOSE(MATCH(TRUE,ISNUMBER(SEARCH({"enero","febrero","marzo","abril","mayo","junio","julio","agosto","septiembre","octubre","noviembre","diciembre"},LOWER(A15))),0), 1,2,3,4,5,6,7,8,9,10,11,12)} -> 4 | F15: =_xlfn.CONCAT(E15,"/1/",D15) -> 4/1/2025 | G15: =TRIM(CLEAN( SUBSTITUTE( SUBSTITUTE( SUBSTITUTE( SUBSTITUTE(C15, CHAR(160), ""), _xlfn.UNICHAR(8203), "" ), "/kg", "" ), "$", "" ) )) -> 27.686,70 | H15: =SUBSTITUTE(G15, ",", ".") -> 27.686.70 | I15: =SUBSTITUTE(H15, ".", "", 1) -> 27686.70 | J15: =VALUE(I15) -> 27686.7 | K15: =VALUE(J15) -> 27686.7
A16: 21 al 27 de abril de 2025​​​ | B16: =LEFT(A16, FIND("de", A16)-2) -> 21 al 27 | C16: ​​$25.759,30​​/kg​ | D16: =IFERROR(MID(A16,FIND("202",A16),4),"") -> 2025 | E16: {=CHOOSE(MATCH(TRUE,ISNUMBER(SEARCH({"enero","febrero","marzo","abril","mayo","junio","julio","agosto","septiembre","octubre","noviembre","diciembre"},LOWER(A16))),0), 1,2,3,4,5,6,7,8,9,10,11,12)} -> 4 | F16: =_xlfn.CONCAT(E16,"/1/",D16) -> 4/1/2025 | G16: =TRIM(CLEAN( SUBSTITUTE( SUBSTITUTE( SUBSTITUTE( SUBSTITUTE(C16, CHAR(160), ""), _xlfn.UNICHAR(8203), "" ), "/kg", "" ), "$", "" ) )) -> 25.759,30 | H16: =SUBSTITUTE(G16, ",", ".") -> 25.759.30 | I16: =SUBSTITUTE(H16, ".", "", 1) -> 25759.30 | J16: =VALUE(I16) -> 25759.3 | K16: =VALUE(J16) -> 25759.3
A17: 14 al 20 de abril de 2025​​​ | B17: =LEFT(A17, FIND("de", A17)-2) -> 14 al 20 | C17: ​​$25.156,00​/kg​ | D17: =IFERROR(MID(A17,FIND("202",A17),4),"") -> 2025 | E17: {=CHOOSE(MATCH(TRUE,ISNUMBER(SEARCH({"enero","febrero","marzo","abril","mayo","junio","julio","agosto","septiembre","octubre","noviembre","diciembre"},LOWER(A17))),0), 1,2,3,4,5,6,7,8,9,10,11,12)} -> 4 | F17: =_xlfn.CONCAT(E17,"/1/",D17) -> 4/1/2025 | G17: =TRIM(CLEAN( SUBSTITUTE( SUBSTITUTE( SUBSTITUTE( SUBSTITUTE(C17, CHAR(160), ""), _xlfn.UNICHAR(8203), "" ), "/kg", "" ), "$", "" ) )) -> 25.156,00 | H17: =SUBSTITUTE(G17, ",", ".") -> 25.156.00 | I17: =SUBSTITUTE(H17, ".", "", 1) -> 25156.00 | J17: =VALUE(I17) -> 25156 | K17: =VALUE(J17) -> 25156
A18: 7 al 13 de abril de 2025​​​ | B18: =LEFT(A18, FIND("de", A18)-2) -> 7 al 13 | C18: ​​$23.842,20​/kg​ | D18: =IFERROR(MID(A18,FIND("202",A18),4),"") -> 2025 | E18: {=CHOOSE(MATCH(TRUE,ISNUMBER(SEARCH({"enero","febrero","marzo","abril","mayo","junio","julio","agosto","septiembre","octubre","noviembre","diciembre"},LOWER(A18))),0), 1,2,3,4,5,6,7,8,9,10,11,12)} -> 4 | F18: =_xlfn.CONCAT(E18,"/1/",D18) -> 4/1/2025 | G18: =TRIM(CLEAN( SUBSTITUTE( SUBSTITUTE( SUBSTITUTE( SUBSTITUTE(C18, CHAR(160), ""), _xlfn.UNICHAR(8203), "" ), "/kg", "" ), "$", "" ) )) -> 23.842,20 | H18: =SUBSTITUTE(G18, ",", ".") -> 23.842.20 | I18: =SUBSTITUTE(H18, ".", "", 1) -> 23842.20 | J18: =VALUE(I18) -> 23842.2 | K18: =VALUE(J18) -> 23842.2
A19: 31 de marzo al 6 de abril de 2025​​​ | B19: 31 al 6 | C19: ​​$23.407,50/kg​ | D19: =IFERROR(MID(A19,FIND("202",A19),4),"") -> 2025 | E19: {=CHOOSE(MATCH(TRUE,ISNUMBER(SEARCH({"enero","febrero","marzo","abril","mayo","junio","julio","agosto","septiembre","octubre","noviembre","diciembre"},LOWER(A19))),0), 1,2,3,4,5,6,7,8,9,10,11,12)} -> 3 | F19: =_xlfn.CONCAT(E19,"/1/",D19) -> 3/1/2025 | G19: =TRIM(CLEAN( SUBSTITUTE( SUBSTITUTE( SUBSTITUTE( SUBSTITUTE(C19, CHAR(160), ""), _xlfn.UNICHAR(8203), "" ), "/kg", "" ), "$", "" ) )) -> 23.407,50 | H19: =SUBSTITUTE(G19, ",", ".") -> 23.407.50 | I19: =SUBSTITUTE(H19, ".", "", 1) -> 23407.50 | J19: =VALUE(I19) -> 23407.5 | K19: =VALUE(J19) -> 23407.5
A20: 24 al 30 de marzo de 2025​​​ | B20: =LEFT(A20, FIND("de", A20)-2) -> 24 al 30 | C20: ​​$23.730,80/kg​ | D20: =IFERROR(MID(A20,FIND("202",A20),4),"") -> 2025 | E20: {=CHOOSE(MATCH(TRUE,ISNUMBER(SEARCH({"enero","febrero","marzo","abril","mayo","junio","julio","agosto","septiembre","octubre","noviembre","diciembre"},LOWER(A20))),0), 1,2,3,4,5,6,7,8,9,10,11,12)} -> 3 | F20: =_xlfn.CONCAT(E20,"/1/",D20) -> 3/1/2025 | G20: =TRIM(CLEAN( SUBSTITUTE( SUBSTITUTE( SUBSTITUTE( SUBSTITUTE(C20, CHAR(160), ""), _xlfn.UNICHAR(8203), "" ), "/kg", "" ), "$", "" ) )) -> 23.730,80 | H20: =SUBSTITUTE(G20, ",", ".") -> 23.730.80 | I20: =SUBSTITUTE(H20, ".", "", 1) -> 23730.80 | J20: =VALUE(I20) -> 23730.8 | K20: =VALUE(J20) -> 23730.8
A21: 17 al 23 de marzo de 2025​​​ | B21: =LEFT(A21, FIND("de", A21)-2) -> 17 al 23 | C21: ​​$22.958,20/kg​ | D21: =IFERROR(MID(A21,FIND("202",A21),4),"") -> 2025 | E21: {=CHOOSE(MATCH(TRUE,ISNUMBER(SEARCH({"enero","febrero","marzo","abril","mayo","junio","julio","agosto","septiembre","octubre","noviembre","diciembre"},LOWER(A21))),0), 1,2,3,4,5,6,7,8,9,10,11,12)} -> 3 | F21: =_xlfn.CONCAT(E21,"/1/",D21) -> 3/1/2025 | G21: =TRIM(CLEAN( SUBSTITUTE( SUBSTITUTE( SUBSTITUTE( SUBSTITUTE(C21, CHAR(160), ""), _xlfn.UNICHAR(8203), "" ), "/kg", "" ), "$", "" ) )) -> 22.958,20 | H21: =SUBSTITUTE(G21, ",", ".") -> 22.958.20 | I21: =SUBSTITUTE(H21, ".", "", 1) -> 22958.20 | J21: =VALUE(I21) -> 22958.2 | K21: =VALUE(J21) -> 22958.2
A22: ​10 al 17 de marzo de 2025​​​ | B22: =LEFT(A22, FIND("de", A22)-2) -> ​10 al 17 | C22: ​​$23.462,80/kg​ | D22: =IFERROR(MID(A22,FIND("202",A22),4),"") -> 2025 | E22: {=CHOOSE(MATCH(TRUE,ISNUMBER(SEARCH({"enero","febrero","marzo","abril","mayo","junio","julio","agosto","septiembre","octubre","noviembre","diciembre"},LOWER(A22))),0), 1,2,3,4,5,6,7,8,9,10,11,12)} -> 3 | F22: =_xlfn.CONCAT(E22,"/1/",D22) -> 3/1/2025 | G22: =TRIM(CLEAN( SUBSTITUTE( SUBSTITUTE( SUBSTITUTE( SUBSTITUTE(C22, CHAR(160), ""), _xlfn.UNICHAR(8203), "" ), "/kg", "" ), "$", "" ) )) -> 23.462,80 | H22: =SUBSTITUTE(G22, ",", ".") -> 23.462.80 | I22: =SUBSTITUTE(H22, ".", "", 1) -> 23462.80 | J22: =VALUE(I22) -> 23462.8 | K22: =VALUE(J22) -> 23462.8
A23: 3 al 9 de marzo de 2025​​ | B23: =LEFT(A23, FIND("de", A23)-2) -> 3 al 9 | C23: ​​$26.468,30​​​​/kg | D23: =IFERROR(MID(A23,FIND("202",A23),4),"") -> 2025 | E23: {=CHOOSE(MATCH(TRUE,ISNUMBER(SEARCH({"enero","febrero","marzo","abril","mayo","junio","julio","agosto","septiembre","octubre","noviembre","diciembre"},LOWER(A23))),0), 1,2,3,4,5,6,7,8,9,10,11,12)} -> 3 | F23: =_xlfn.CONCAT(E23,"/1/",D23) -> 3/1/2025 | G23: =TRIM(CLEAN( SUBSTITUTE( SUBSTITUTE( SUBSTITUTE( SUBSTITUTE(C23, CHAR(160), ""), _xlfn.UNICHAR(8203), "" ), "/kg", "" ), "$", "" ) )) -> 26.468,30 | H23: =SUBSTITUTE(G23, ",", ".") -> 26.468.30 | I23: =SUBSTITUTE(H23, ".", "", 1) -> 26468.30 | J23: =VALUE(I23) -> 26468.3 | K23: =VALUE(J23) -> 26468.3
A24: 24 de febrero al 2 de marzo de 2025​​ | B24: 24 al 2 | C24: ​​$28.345,00/kg​​​​​​ | D24: =IFERROR(MID(A24,FIND("202",A24),4),"") -> 2025 | E24: {=CHOOSE(MATCH(TRUE,ISNUMBER(SEARCH({"enero","febrero","marzo","abril","mayo","junio","julio","agosto","septiembre","octubre","noviembre","diciembre"},LOWER(A24))),0), 1,2,3,4,5,6,7,8,9,10,11,12)} -> 2 | F24: =_xlfn.CONCAT(E24,"/1/",D24) -> 2/1/2025 | G24: =TRIM(CLEAN( SUBSTITUTE( SUBSTITUTE( SUBSTITUTE( SUBSTITUTE(C24, CHAR(160), ""), _xlfn.UNICHAR(8203), "" ), "/kg", "" ), "$", "" ) )) -> 28.345,00 | H24: =SUBSTITUTE(G24, ",", ".") -> 28.345.00 | I24: =SUBSTITUTE(H24, ".", "", 1) -> 28345.00 | J24: =VALUE(I24) -> 28345 | K24: =VALUE(J24) -> 28345
A25: 17 al 23 de febrero de 2025​ | B25: =LEFT(A25, FIND("de", A25)-2) -> 17 al 23 | C25: ​​$30.533,70/kg​​​​​​ | D25: =IFERROR(MID(A25,FIND("202",A25),4),"") -> 2025 | E25: {=CHOOSE(MATCH(TRUE,ISNUMBER(SEARCH({"enero","febrero","marzo","abril","mayo","junio","julio","agosto","septiembre","octubre","noviembre","diciembre"},LOWER(A25))),0), 1,2,3,4,5,6,7,8,9,10,11,12)} -> 2 | F25: =_xlfn.CONCAT(E25,"/1/",D25) -> 2/1/2025 | G25: =TRIM(CLEAN( SUBSTITUTE( SUBSTITUTE( SUBSTITUTE( SUBSTITUTE(C25, CHAR(160), ""), _xlfn.UNICHAR(8203), "" ), "/kg", "" ), "$", "" ) )) -> 30.533,70 | H25: =SUBSTITUTE(G25, ",", ".") -> 30.533.70 | I25: =SUBSTITUTE(H25, ".", "", 1) -> 30533.70 | J25: =VALUE(I25) -> 30533.7 | K25: =VALUE(J25) -> 30533.7
A26: 10 al 16 de febrero de 2025​ | B26: =LEFT(A26, FIND("de", A26)-2) -> 10 al 16 | C26: ​​$31.623,50/kg​​​​ | D26: =IFERROR(MID(A26,FIND("202",A26),4),"") -> 2025 | E26: {=CHOOSE(MATCH(TRUE,ISNUMBER(SEARCH({"enero","febrero","marzo","abril","mayo","junio","julio","agosto","septiembre","octubre","noviembre","diciembre"},LOWER(A26))),0), 1,2,3,4,5,6,7,8,9,10,11,12)} -> 2 | F26: =_xlfn.CONCAT(E26,"/1/",D26) -> 2/1/2025 | G26: =TRIM(CLEAN( SUBSTITUTE( SUBSTITUTE( SUBSTITUTE( SUBSTITUTE(C26, CHAR(160), ""), _xlfn.UNICHAR(8203), "" ), "/kg", "" ), "$", "" ) )) -> 31.623,50 | H26: =SUBSTITUTE(G26, ",", ".") -> 31.623.50 | I26: =SUBSTITUTE(H26, ".", "", 1) -> 31623.50 | J26: =VALUE(I26) -> 31623.5 | K26: =VALUE(J26) -> 31623.5
A27: 3 al 9 de febrero de 2025​ | B27: =LEFT(A27, FIND("de", A27)-2) -> 3 al 9 | C27: ​​$33.611,00/kg​​​​ | D27: =IFERROR(MID(A27,FIND("202",A27),4),"") -> 2025 | E27: {=CHOOSE(MATCH(TRUE,ISNUMBER(SEARCH({"enero","febrero","marzo","abril","mayo","junio","julio","agosto","septiembre","octubre","noviembre","diciembre"},LOWER(A27))),0), 1,2,3,4,5,6,7,8,9,10,11,12)} -> 2 | F27: =_xlfn.CONCAT(E27,"/1/",D27) -> 2/1/2025 | G27: =TRIM(CLEAN( SUBSTITUTE( SUBSTITUTE( SUBSTITUTE( SUBSTITUTE(C27, CHAR(160), ""), _xlfn.UNICHAR(8203), "" ), "/kg", "" ), "$", "" ) )) -> 33.611,00 | H27: =SUBSTITUTE(G27, ",", ".") -> 33.611.00 | I27: =SUBSTITUTE(H27, ".", "", 1) -> 33611.00 | J27: =VALUE(I27) -> 33611 | K27: =VALUE(J27) -> 33611
A28: 27 enero al 2 de febrero de 2025 | B28: 27 al 2 | C28: ​​$33.831,30/kg​​​​ | D28: =IFERROR(MID(A28,FIND("202",A28),4),"") -> 2025 | E28: {=CHOOSE(MATCH(TRUE,ISNUMBER(SEARCH({"enero","febrero","marzo","abril","mayo","junio","julio","agosto","septiembre","octubre","noviembre","diciembre"},LOWER(A28))),0), 1,2,3,4,5,6,7,8,9,10,11,12)} -> 1 | F28: =_xlfn.CONCAT(E28,"/1/",D28) -> 1/1/2025 | G28: =TRIM(CLEAN( SUBSTITUTE( SUBSTITUTE( SUBSTITUTE( SUBSTITUTE(C28, CHAR(160), ""), _xlfn.UNICHAR(8203), "" ), "/kg", "" ), "$", "" ) )) -> 33.831,30 | H28: =SUBSTITUTE(G28, ",", ".") -> 33.831.30 | I28: =SUBSTITUTE(H28, ".", "", 1) -> 33831.30 | J28: =VALUE(I28) -> 33831.3 | K28: =VALUE(J28) -> 33831.3
A29: 20 al 26 de enero de 2025 | B29: =LEFT(A29, FIND("de", A29)-2) -> 20 al 26 | C29: ​​$33.817,80​​​​/kg​ | D29: =IFERROR(MID(A29,FIND("202",A29),4),"") -> 2025 | E29: {=CHOOSE(MATCH(TRUE,ISNUMBER(SEARCH({"enero","febrero","marzo","abril","mayo","junio","julio","agosto","septiembre","octubre","noviembre","diciembre"},LOWER(A29))),0), 1,2,3,4,5,6,7,8,9,10,11,12)} -> 1 | F29: =_xlfn.CONCAT(E29,"/1/",D29) -> 1/1/2025 | G29: =TRIM(CLEAN( SUBSTITUTE( SUBSTITUTE( SUBSTITUTE( SUBSTITUTE(C29, CHAR(160), ""), _xlfn.UNICHAR(8203), "" ), "/kg", "" ), "$", "" ) )) -> 33.817,80 | H29: =SUBSTITUTE(G29, ",", ".") -> 33.817.80 | I29: =SUBSTITUTE(H29, ".", "", 1) -> 33817.80 | J29: =VALUE(I29) -> 33817.8 | K29: =VALUE(J29) -> 33817.8
A30: 13 al 19 de enero de 2025 | B30: =LEFT(A30, FIND("de", A30)-2) -> 13 al 19 | C30: ​​$34.229,20​​​​/kg | D30: =IFERROR(MID(A30,FIND("202",A30),4),"") -> 2025 | E30: {=CHOOSE(MATCH(TRUE,ISNUMBER(SEARCH({"enero","febrero","marzo","abril","mayo","junio","julio","agosto","septiembre","octubre","noviembre","diciembre"},LOWER(A30))),0), 1,2,3,4,5,6,7,8,9,10,11,12)} -> 1 | F30: =_xlfn.CONCAT(E30,"/1/",D30) -> 1/1/2025 | G30: =TRIM(CLEAN( SUBSTITUTE( SUBSTITUTE( SUBSTITUTE( SUBSTITUTE(C30, CHAR(160), ""), _xlfn.UNICHAR(8203), "" ), "/kg", "" ), "$", "" ) )) -> 34.229,20 | H30: =SUBSTITUTE(G30, ",", ".") -> 34.229.20 | I30: =SUBSTITUTE(H30, ".", "", 1) -> 34229.20 | J30: =VALUE(I30) -> 34229.2 | K30: =VALUE(J30) -> 34229.2
A31: 6 al 12 de enero de 2025 | B31: =LEFT(A31, FIND("de", A31)-2) -> 6 al 12 | C31: ​​$34.633,50​​​​​/kg | D31: =IFERROR(MID(A31,FIND("202",A31),4),"") -> 2025 | E31: {=CHOOSE(MATCH(TRUE,ISNUMBER(SEARCH({"enero","febrero","marzo","abril","mayo","junio","julio","agosto","septiembre","octubre","noviembre","diciembre"},LOWER(A31))),0), 1,2,3,4,5,6,7,8,9,10,11,12)} -> 1 | F31: =_xlfn.CONCAT(E31,"/1/",D31) -> 1/1/2025 | G31: =TRIM(CLEAN( SUBSTITUTE( SUBSTITUTE( SUBSTITUTE( SUBSTITUTE(C31, CHAR(160), ""), _xlfn.UNICHAR(8203), "" ), "/kg", "" ), "$", "" ) )) -> 34.633,50 | H31: =SUBSTITUTE(G31, ",", ".") -> 34.633.50 | I31: =SUBSTITUTE(H31, ".", "", 1) -> 34633.50 | J31: =VALUE(I31) -> 34633.5 | K31: =VALUE(J31) -> 34633.5
A32: 30 diciembre de 2024 al 5 enero de 2025 | B32: 30 al 5 | C32: ​​$34.900,80​​​​ | D32: =IFERROR(MID(A32,FIND("202",A32),4),"") -> 2024 | E32: {=CHOOSE(MATCH(TRUE,ISNUMBER(SEARCH({"enero","febrero","marzo","abril","mayo","junio","julio","agosto","septiembre","octubre","noviembre","diciembre"},LOWER(A32))),0), 1,2,3,4,5,6,7,8,9,10,11,12)} -> 1 | F32: =_xlfn.CONCAT(E32,"/1/",D32) -> 1/1/2024 | G32: =TRIM(CLEAN( SUBSTITUTE( SUBSTITUTE( SUBSTITUTE( SUBSTITUTE(C32, CHAR(160), ""), _xlfn.UNICHAR(8203), "" ), "/kg", "" ), "$", "" ) )) -> 34.900,80 | H32: =SUBSTITUTE(G32, ",", ".") -> 34.900.80 | I32: =SUBSTITUTE(H32, ".", "", 1) -> 34900.80 | J32: =VALUE(I32) -> 34900.8 | K32: =VALUE(J32) -> 34900.8
A33: 16 al 22 ​d​e diciembre ​​​​de 2024 ​​​​​​​​​​​​​​ | B33: 26 al 22 | C33: ​​$33.968.​​​3​0​​​​ | D33: =IFERROR(MID(A33,FIND("202",A33),4),"") -> 2024 | E33: {=CHOOSE(MATCH(TRUE,ISNUMBER(SEARCH({"enero","febrero","marzo","abril","mayo","junio","julio","agosto","septiembre","octubre","noviembre","diciembre"},LOWER(A33))),0), 1,2,3,4,5,6,7,8,9,10,11,12)} -> 12 | F33: =_xlfn.CONCAT(E33,"/1/",D33) -> 12/1/2024 | G33: =TRIM(CLEAN( SUBSTITUTE( SUBSTITUTE( SUBSTITUTE( SUBSTITUTE(C33, CHAR(160), ""), _xlfn.UNICHAR(8203), "" ), "/kg", "" ), "$", "" ) )) -> 33.968.30 | H33: =SUBSTITUTE(G33, ",", ".") -> 33.968.30 | I33: =SUBSTITUTE(H33, ".", "", 1) -> 33968.30 | J33: =VALUE(I33) -> 33968.3 | K33: =VALUE(J33) -> 33968.3
A34: 09 al 15 ​d​e diciembre ​​​​de 2024 ​​​​​​​​​​​​​​ | B34: 9 al 15 | C34: ​​$32.459.​​​70​​​​ | D34: =IFERROR(MID(A34,FIND("202",A34),4),"") -> 2024 | E34: {=CHOOSE(MATCH(TRUE,ISNUMBER(SEARCH({"enero","febrero","marzo","abril","mayo","junio","julio","agosto","septiembre","octubre","noviembre","diciembre"},LOWER(A34))),0), 1,2,3,4,5,6,7,8,9,10,11,12)} -> 12 | F34: =_xlfn.CONCAT(E34,"/1/",D34) -> 12/1/2024 | G34: =TRIM(CLEAN( SUBSTITUTE( SUBSTITUTE( SUBSTITUTE( SUBSTITUTE(C34, CHAR(160), ""), _xlfn.UNICHAR(8203), "" ), "/kg", "" ), "$", "" ) )) -> 32.459.70 | H34: =SUBSTITUTE(G34, ",", ".") -> 32.459.70 | I34: =SUBSTITUTE(H34, ".", "", 1) -> 32459.70 | J34: =VALUE(I34) -> 32459.7 | K34: =VALUE(J34) -> 32459.7
A35: 02 al 08 ​d​e diciem​​bre ​​​​de 2024 ​​​​​​​​​​​​​​ | B35: 2 al 8 | C35: ​​$32.570.​​​70​​​​ | D35: =IFERROR(MID(A35,FIND("202",A35),4),"") -> 2024 | E35: 12 | F35: =_xlfn.CONCAT(E35,"/1/",D35) -> 12/1/2024 | G35: =TRIM(CLEAN( SUBSTITUTE( SUBSTITUTE( SUBSTITUTE( SUBSTITUTE(C35, CHAR(160), ""), _xlfn.UNICHAR(8203), "" ), "/kg", "" ), "$", "" ) )) -> 32.570.70 | H35: =SUBSTITUTE(G35, ",", ".") -> 32.570.70 | I35: =SUBSTITUTE(H35, ".", "", 1) -> 32570.70 | J35: =VALUE(I35) -> 32570.7 | K35: =VALUE(J35) -> 32570.7
A36: 25 de noviembre al 01 ​d​​​e diciembre ​​​​de 2024 ​​​​​​​​​​​​​​ | B36: 25 al 1 | C36: ​​$32.570.​​​00​​​​ | D36: =IFERROR(MID(A36,FIND("202",A36),4),"") -> 2024 | E36: {=CHOOSE(MATCH(TRUE,ISNUMBER(SEARCH({"enero","febrero","marzo","abril","mayo","junio","julio","agosto","septiembre","octubre","noviembre","diciembre"},LOWER(A36))),0), 1,2,3,4,5,6,7,8,9,10,11,12)} -> 11 | F36: =_xlfn.CONCAT(E36,"/1/",D36) -> 11/1/2024 | G36: =TRIM(CLEAN( SUBSTITUTE( SUBSTITUTE( SUBSTITUTE( SUBSTITUTE(C36, CHAR(160), ""), _xlfn.UNICHAR(8203), "" ), "/kg", "" ), "$", "" ) )) -> 32.570.00 | H36: =SUBSTITUTE(G36, ",", ".") -> 32.570.00 | I36: =SUBSTITUTE(H36, ".", "", 1) -> 32570.00 | J36: =VALUE(I36) -> 32570 | K36: =VALUE(J36) -> 32570
A37: 18 al 24 ​d​e noviembre ​​​​de 2024 ​​​​​​​​​​​​​​ | B37: 18 al 24 | C37: ​​$31.529.​​​20​​​​ | D37: =IFERROR(MID(A37,FIND("202",A37),4),"") -> 2024 | E37: {=CHOOSE(MATCH(TRUE,ISNUMBER(SEARCH({"enero","febrero","marzo","abril","mayo","junio","julio","agosto","septiembre","octubre","noviembre","diciembre"},LOWER(A37))),0), 1,2,3,4,5,6,7,8,9,10,11,12)} -> 11 | F37: =_xlfn.CONCAT(E37,"/1/",D37) -> 11/1/2024 | G37: =TRIM(CLEAN( SUBSTITUTE( SUBSTITUTE( SUBSTITUTE( SUBSTITUTE(C37, CHAR(160), ""), _xlfn.UNICHAR(8203), "" ), "/kg", "" ), "$", "" ) )) -> 31.529.20 | H37: =SUBSTITUTE(G37, ",", ".") -> 31.529.20 | I37: =SUBSTITUTE(H37, ".", "", 1) -> 31529.20 | J37: =VALUE(I37) -> 31529.2 | K37: =VALUE(J37) -> 31529.2
A38: ​11 al 17 ​d​e noviembre ​​​​de 2024 ​​​​​​​​​​​​​​ | B38: 11 al 17 | C38: ​​$30.069.​​​20​​​​ | D38: =IFERROR(MID(A38,FIND("202",A38),4),"") -> 2024 | E38: {=CHOOSE(MATCH(TRUE,ISNUMBER(SEARCH({"enero","febrero","marzo","abril","mayo","junio","julio","agosto","septiembre","octubre","noviembre","diciembre"},LOWER(A38))),0), 1,2,3,4,5,6,7,8,9,10,11,12)} -> 11 | F38: =_xlfn.CONCAT(E38,"/1/",D38) -> 11/1/2024 | G38: =TRIM(CLEAN( SUBSTITUTE( SUBSTITUTE( SUBSTITUTE( SUBSTITUTE(C38, CHAR(160), ""), _xlfn.UNICHAR(8203), "" ), "/kg", "" ), "$", "" ) )) -> 30.069.20 | H38: =SUBSTITUTE(G38, ",", ".") -> 30.069.20 | I38: =SUBSTITUTE(H38, ".", "", 1) -> 30069.20 | J38: =VALUE(I38) -> 30069.2 | K38: =VALUE(J38) -> 30069.2
A39: 04 al 10 ​d​e noviembre ​​​​de 2024 ​​​​​​​​​​​​​​ | B39: 4 al 10 | C39: ​​$31.241.​​​3​​​​0​​​​ | D39: =IFERROR(MID(A39,FIND("202",A39),4),"") -> 2024 | E39: {=CHOOSE(MATCH(TRUE,ISNUMBER(SEARCH({"enero","febrero","marzo","abril","mayo","junio","julio","agosto","septiembre","octubre","noviembre","diciembre"},LOWER(A39))),0), 1,2,3,4,5,6,7,8,9,10,11,12)} -> 11 | F39: =_xlfn.CONCAT(E39,"/1/",D39) -> 11/1/2024 | G39: =TRIM(CLEAN( SUBSTITUTE( SUBSTITUTE( SUBSTITUTE( SUBSTITUTE(C39, CHAR(160), ""), _xlfn.UNICHAR(8203), "" ), "/kg", "" ), "$", "" ) )) -> 31.241.30 | H39: =SUBSTITUTE(G39, ",", ".") -> 31.241.30 | I39: =SUBSTITUTE(H39, ".", "", 1) -> 31241.30 | J39: =VALUE(I39) -> 31241.3 | K39: =VALUE(J39) -> 31241.3
A40: 28 de octubre al 03 ​d​e noviembre ​​​​de 2024 ​​​​​​​​​​​​​​ | B40: 28 al 3 | C40: ​​$29.553.​​​7​​​0​​​​ | D40: =IFERROR(MID(A40,FIND("202",A40),4),"") -> 2024 | E40: {=CHOOSE(MATCH(TRUE,ISNUMBER(SEARCH({"enero","febrero","marzo","abril","mayo","junio","julio","agosto","septiembre","octubre","noviembre","diciembre"},LOWER(A40))),0), 1,2,3,4,5,6,7,8,9,10,11,12)} -> 10 | F40: =_xlfn.CONCAT(E40,"/1/",D40) -> 10/1/2024 | G40: =TRIM(CLEAN( SUBSTITUTE( SUBSTITUTE( SUBSTITUTE( SUBSTITUTE(C40, CHAR(160), ""), _xlfn.UNICHAR(8203), "" ), "/kg", "" ), "$", "" ) )) -> 29.553.70 | H40: =SUBSTITUTE(G40, ",", ".") -> 29.553.70 | I40: =SUBSTITUTE(H40, ".", "", 1) -> 29553.70 | J40: =VALUE(I40) -> 29553.7 | K40: =VALUE(J40) -> 29553.7
...

Sheet Cleaned_Colombian_Cacao
A1: date | B1: week_raw | C1: week | D1: price_cop_per_kg
A2: 41456 | B2: 1 - 7 | C2: =SUBSTITUTE(B2,"-","–") -> 1 – 7 | D2: 3762.5
A3: 41456 | B3: 8 - 4 | C3: =SUBSTITUTE(B3,"-","–") -> 8 – 4 | D3: 3797.5
A4: 41456 | B4: 15 - 21 | C4: =SUBSTITUTE(B4,"-","–") -> 15 – 21 | D4: 3737.5
A5: 41456 | B5: 22 - 28 | C5: =SUBSTITUTE(B5,"-","–") -> 22 – 28 | D5: 3797.5
A6: 41487 | B6: 29 - 4 | C6: =SUBSTITUTE(B6,"-","–") -> 29 – 4 | D6: 3937.5
A7: 41487 | B7: 5 - 1 | C7: =SUBSTITUTE(B7,"-","–") -> 5 – 1 | D7: 3897.5
A8: 41487 | B8: 12 - 18 | C8: =SUBSTITUTE(B8,"-","–") -> 12 – 18 | D8: 4012.5
A9: 41487 | B9: 19 - 25 | C9: =SUBSTITUTE(B9,"-","–") -> 19 – 25 | D9: 4137.5
A10: 41487 | B10: 26 - 1 | C10: =SUBSTITUTE(B10,"-","–") -> 26 – 1 | D10: 4217.5
A11: 41518 | B11: 2 - 8 | C11: =SUBSTITUTE(B11,"-","–") -> 2 – 8 | D11: 4287.5
A12: 41518 | B12: 9 - 5 | C12: =SUBSTITUTE(B12,"-","–") -> 9 – 5 | D12: 4287.5
A13: 41518 | B13: 16 - 22 | C13: =SUBSTITUTE(B13,"-","–") -> 16 – 22 | D13: 4462.5
... A577: 45474 | B577: 15 - 21 | C577: =SUBSTITUTE(B577,"-","–") -> 15 – 21 | D577: 29218
A578: 7/1/2024 | B578: 22 - 28 | C578: =SUBSTITUTE(B578,"-","–") -> 22 – 28 | D578: 29380.8
A579: 7/1/2024 | B579: 29 - 04 | C579: =SUBSTITUTE(B579,"-","–") -> 29 – 04 | D579: 30001.3
A580: 8/1/2024 | B580: 05 - 11 | C580: =SUBSTITUTE(B580,"-","–") -> 05 – 11 | D580: 29737
A581: 8/1/2024 | B581: 12 - 18 | C581: =SUBSTITUTE(B581,"-","–") -> 12 – 18 | D581: 30532.5
A582: 8/1/2024 | B582: 19 - 25 | C582: =SUBSTITUTE(B582,"-","–") -> 19 – 25 | D582: 28863.7
A583: 8/1/2024 | B583: 26 - 01 | C583: =SUBSTITUTE(B583,"-","–") -> 26 – 01 | D583: 29505
A584: 9/1/2024 | B584: 02 - 08 | C584: =SUBSTITUTE(B584,"-","–") -> 02 – 08 | D584: 31460.8
A585: 9/1/2024 | B585: 09 - 15 | C585: =SUBSTITUTE(B585,"-","–") -> 09 – 15 | D585: 29681
A586: 9/1/2024 | B586: 16 - 22 | C586: =SUBSTITUTE(B586,"-","–") -> 16 – 22 | D586: 30525.8
A587: 9/1/2024 | B587: 23 - 29 | C587: =SUBSTITUTE(B587,"-","–") -> 23 – 29 | D587: 30882.2
A588: 9/1/2024 | B588: 30 - 06 | C588: =SUBSTITUTE(B588,"-","–") -> 30 – 06 | D588: 31437.7
A589: 10/1/2024 | B589: 07 - 13 | C589: =SUBSTITUTE(B589,"-","–") -> 07 – 13 | D589: 29845
... A630: 7/1/2025 | B630: 28 - 03 | C630: =SUBSTITUTE(B630,"-","–") -> 28 – 03 | D630: 23747

Sheet Monthly_Colombian_Cacao
A1: raw_date | B1: date | C1: month_sum | D1: number_weeks | E1: avg_month | F1: trm_usd | G1: price_usd_metric_kilogram | H1: price_usd_metric_ton
